2024-07-13 11:03:34.619255: I tensorflow/core/platform/cpu_feature_guard.cc:182] This TensorFlow binary is optimized to use available CPU instructions in performance-critical operations.
To enable the following instructions: AVX2 AVX512F FMA, in other operations, rebuild TensorFlow with the appropriate compiler flags.
2024-07-13 11:03:35.727847: W tensorflow/compiler/tf2tensorrt/utils/py_utils.cc:38] TF-TRT Warning: Could not find TensorRT
Using cuda:1
Process Worker<SafetyAsyncVectorEnv>-9:
Traceback (most recent call last):
  File "/home/zzydty/sim/safety-gymnasium-main/safety_gymnasium/vector/async_vector_env.py", line 253, in _worker_shared_memory
    command, data = pipe.recv()
  File "/home/zzydty/miniconda3/envs/safety/lib/python3.8/multiprocessing/connection.py", line 250, in recv
    buf = self._recv_bytes()
  File "/home/zzydty/miniconda3/envs/safety/lib/python3.8/multiprocessing/connection.py", line 414, in _recv_bytes
    buf = self._recv(4)
  File "/home/zzydty/miniconda3/envs/safety/lib/python3.8/multiprocessing/connection.py", line 383, in _recv
    raise EOFError
EOFError

During handling of the above exception, another exception occurred:

Traceback (most recent call last):
  File "/home/zzydty/miniconda3/envs/safety/lib/python3.8/multiprocessing/process.py", line 315, in _bootstrap
    self.run()
  File "/home/zzydty/miniconda3/envs/safety/lib/python3.8/multiprocessing/process.py", line 108, in run
    self._target(*self._args, **self._kwargs)
  File "/home/zzydty/sim/safety-gymnasium-main/safety_gymnasium/vector/async_vector_env.py", line 313, in _worker_shared_memory
    pipe.send((None, False))
  File "/home/zzydty/miniconda3/envs/safety/lib/python3.8/multiprocessing/connection.py", line 206, in send
    self._send_bytes(_ForkingPickler.dumps(obj))
  File "/home/zzydty/miniconda3/envs/safety/lib/python3.8/multiprocessing/connection.py", line 411, in _send_bytes
    self._send(header + buf)
  File "/home/zzydty/miniconda3/envs/safety/lib/python3.8/multiprocessing/connection.py", line 368, in _send
    n = write(self._handle, buf)
BrokenPipeError: [Errno 32] Broken pipe
Process Worker<SafetyAsyncVectorEnv>-8:
Traceback (most recent call last):
  File "/home/zzydty/sim/safety-gymnasium-main/safety_gymnasium/vector/async_vector_env.py", line 253, in _worker_shared_memory
    command, data = pipe.recv()
  File "/home/zzydty/miniconda3/envs/safety/lib/python3.8/multiprocessing/connection.py", line 250, in recv
    buf = self._recv_bytes()
  File "/home/zzydty/miniconda3/envs/safety/lib/python3.8/multiprocessing/connection.py", line 414, in _recv_bytes
    buf = self._recv(4)
  File "/home/zzydty/miniconda3/envs/safety/lib/python3.8/multiprocessing/connection.py", line 383, in _recv
    raise EOFError
EOFError

During handling of the above exception, another exception occurred:

Traceback (most recent call last):
  File "/home/zzydty/miniconda3/envs/safety/lib/python3.8/multiprocessing/process.py", line 315, in _bootstrap
    self.run()
  File "/home/zzydty/miniconda3/envs/safety/lib/python3.8/multiprocessing/process.py", line 108, in run
    self._target(*self._args, **self._kwargs)
  File "/home/zzydty/sim/safety-gymnasium-main/safety_gymnasium/vector/async_vector_env.py", line 313, in _worker_shared_memory
    pipe.send((None, False))
  File "/home/zzydty/miniconda3/envs/safety/lib/python3.8/multiprocessing/connection.py", line 206, in send
    self._send_bytes(_ForkingPickler.dumps(obj))
  File "/home/zzydty/miniconda3/envs/safety/lib/python3.8/multiprocessing/connection.py", line 411, in _send_bytes
    self._send(header + buf)
  File "/home/zzydty/miniconda3/envs/safety/lib/python3.8/multiprocessing/connection.py", line 368, in _send
    n = write(self._handle, buf)
BrokenPipeError: [Errno 32] Broken pipe
Process Worker<SafetyAsyncVectorEnv>-7:
Traceback (most recent call last):
  File "/home/zzydty/sim/safety-gymnasium-main/safety_gymnasium/vector/async_vector_env.py", line 253, in _worker_shared_memory
    command, data = pipe.recv()
  File "/home/zzydty/miniconda3/envs/safety/lib/python3.8/multiprocessing/connection.py", line 250, in recv
    buf = self._recv_bytes()
  File "/home/zzydty/miniconda3/envs/safety/lib/python3.8/multiprocessing/connection.py", line 414, in _recv_bytes
    buf = self._recv(4)
  File "/home/zzydty/miniconda3/envs/safety/lib/python3.8/multiprocessing/connection.py", line 383, in _recv
    raise EOFError
EOFError

During handling of the above exception, another exception occurred:

Traceback (most recent call last):
  File "/home/zzydty/miniconda3/envs/safety/lib/python3.8/multiprocessing/process.py", line 315, in _bootstrap
    self.run()
  File "/home/zzydty/miniconda3/envs/safety/lib/python3.8/multiprocessing/process.py", line 108, in run
    self._target(*self._args, **self._kwargs)
  File "/home/zzydty/sim/safety-gymnasium-main/safety_gymnasium/vector/async_vector_env.py", line 313, in _worker_shared_memory
    pipe.send((None, False))
  File "/home/zzydty/miniconda3/envs/safety/lib/python3.8/multiprocessing/connection.py", line 206, in send
    self._send_bytes(_ForkingPickler.dumps(obj))
  File "/home/zzydty/miniconda3/envs/safety/lib/python3.8/multiprocessing/connection.py", line 411, in _send_bytes
    self._send(header + buf)
  File "/home/zzydty/miniconda3/envs/safety/lib/python3.8/multiprocessing/connection.py", line 368, in _send
    n = write(self._handle, buf)
BrokenPipeError: [Errno 32] Broken pipe
Process Worker<SafetyAsyncVectorEnv>-6:
Traceback (most recent call last):
  File "/home/zzydty/sim/safety-gymnasium-main/safety_gymnasium/vector/async_vector_env.py", line 253, in _worker_shared_memory
    command, data = pipe.recv()
  File "/home/zzydty/miniconda3/envs/safety/lib/python3.8/multiprocessing/connection.py", line 250, in recv
    buf = self._recv_bytes()
  File "/home/zzydty/miniconda3/envs/safety/lib/python3.8/multiprocessing/connection.py", line 414, in _recv_bytes
    buf = self._recv(4)
  File "/home/zzydty/miniconda3/envs/safety/lib/python3.8/multiprocessing/connection.py", line 383, in _recv
    raise EOFError
EOFError

During handling of the above exception, another exception occurred:

Traceback (most recent call last):
  File "/home/zzydty/miniconda3/envs/safety/lib/python3.8/multiprocessing/process.py", line 315, in _bootstrap
    self.run()
  File "/home/zzydty/miniconda3/envs/safety/lib/python3.8/multiprocessing/process.py", line 108, in run
    self._target(*self._args, **self._kwargs)
  File "/home/zzydty/sim/safety-gymnasium-main/safety_gymnasium/vector/async_vector_env.py", line 313, in _worker_shared_memory
    pipe.send((None, False))
  File "/home/zzydty/miniconda3/envs/safety/lib/python3.8/multiprocessing/connection.py", line 206, in send
    self._send_bytes(_ForkingPickler.dumps(obj))
  File "/home/zzydty/miniconda3/envs/safety/lib/python3.8/multiprocessing/connection.py", line 411, in _send_bytes
    self._send(header + buf)
  File "/home/zzydty/miniconda3/envs/safety/lib/python3.8/multiprocessing/connection.py", line 368, in _send
    n = write(self._handle, buf)
BrokenPipeError: [Errno 32] Broken pipe
Process Worker<SafetyAsyncVectorEnv>-5:
Traceback (most recent call last):
  File "/home/zzydty/sim/safety-gymnasium-main/safety_gymnasium/vector/async_vector_env.py", line 253, in _worker_shared_memory
    command, data = pipe.recv()
  File "/home/zzydty/miniconda3/envs/safety/lib/python3.8/multiprocessing/connection.py", line 250, in recv
    buf = self._recv_bytes()
  File "/home/zzydty/miniconda3/envs/safety/lib/python3.8/multiprocessing/connection.py", line 414, in _recv_bytes
    buf = self._recv(4)
  File "/home/zzydty/miniconda3/envs/safety/lib/python3.8/multiprocessing/connection.py", line 383, in _recv
    raise EOFError
EOFError

During handling of the above exception, another exception occurred:

Traceback (most recent call last):
  File "/home/zzydty/miniconda3/envs/safety/lib/python3.8/multiprocessing/process.py", line 315, in _bootstrap
    self.run()
  File "/home/zzydty/miniconda3/envs/safety/lib/python3.8/multiprocessing/process.py", line 108, in run
    self._target(*self._args, **self._kwargs)
  File "/home/zzydty/sim/safety-gymnasium-main/safety_gymnasium/vector/async_vector_env.py", line 313, in _worker_shared_memory
    pipe.send((None, False))
  File "/home/zzydty/miniconda3/envs/safety/lib/python3.8/multiprocessing/connection.py", line 206, in send
    self._send_bytes(_ForkingPickler.dumps(obj))
  File "/home/zzydty/miniconda3/envs/safety/lib/python3.8/multiprocessing/connection.py", line 411, in _send_bytes
    self._send(header + buf)
  File "/home/zzydty/miniconda3/envs/safety/lib/python3.8/multiprocessing/connection.py", line 368, in _send
    n = write(self._handle, buf)
BrokenPipeError: [Errno 32] Broken pipe
Process Worker<SafetyAsyncVectorEnv>-4:
Traceback (most recent call last):
  File "/home/zzydty/sim/safety-gymnasium-main/safety_gymnasium/vector/async_vector_env.py", line 253, in _worker_shared_memory
    command, data = pipe.recv()
  File "/home/zzydty/miniconda3/envs/safety/lib/python3.8/multiprocessing/connection.py", line 250, in recv
    buf = self._recv_bytes()
  File "/home/zzydty/miniconda3/envs/safety/lib/python3.8/multiprocessing/connection.py", line 414, in _recv_bytes
    buf = self._recv(4)
  File "/home/zzydty/miniconda3/envs/safety/lib/python3.8/multiprocessing/connection.py", line 383, in _recv
    raise EOFError
EOFError

During handling of the above exception, another exception occurred:

Traceback (most recent call last):
  File "/home/zzydty/miniconda3/envs/safety/lib/python3.8/multiprocessing/process.py", line 315, in _bootstrap
    self.run()
  File "/home/zzydty/miniconda3/envs/safety/lib/python3.8/multiprocessing/process.py", line 108, in run
    self._target(*self._args, **self._kwargs)
  File "/home/zzydty/sim/safety-gymnasium-main/safety_gymnasium/vector/async_vector_env.py", line 313, in _worker_shared_memory
    pipe.send((None, False))
  File "/home/zzydty/miniconda3/envs/safety/lib/python3.8/multiprocessing/connection.py", line 206, in send
    self._send_bytes(_ForkingPickler.dumps(obj))
  File "/home/zzydty/miniconda3/envs/safety/lib/python3.8/multiprocessing/connection.py", line 411, in _send_bytes
    self._send(header + buf)
  File "/home/zzydty/miniconda3/envs/safety/lib/python3.8/multiprocessing/connection.py", line 368, in _send
    n = write(self._handle, buf)
BrokenPipeError: [Errno 32] Broken pipe
Process Worker<SafetyAsyncVectorEnv>-3:
Traceback (most recent call last):
  File "/home/zzydty/sim/safety-gymnasium-main/safety_gymnasium/vector/async_vector_env.py", line 253, in _worker_shared_memory
    command, data = pipe.recv()
  File "/home/zzydty/miniconda3/envs/safety/lib/python3.8/multiprocessing/connection.py", line 250, in recv
    buf = self._recv_bytes()
  File "/home/zzydty/miniconda3/envs/safety/lib/python3.8/multiprocessing/connection.py", line 414, in _recv_bytes
    buf = self._recv(4)
  File "/home/zzydty/miniconda3/envs/safety/lib/python3.8/multiprocessing/connection.py", line 383, in _recv
    raise EOFError
EOFError

During handling of the above exception, another exception occurred:

Traceback (most recent call last):
  File "/home/zzydty/miniconda3/envs/safety/lib/python3.8/multiprocessing/process.py", line 315, in _bootstrap
    self.run()
  File "/home/zzydty/miniconda3/envs/safety/lib/python3.8/multiprocessing/process.py", line 108, in run
    self._target(*self._args, **self._kwargs)
  File "/home/zzydty/sim/safety-gymnasium-main/safety_gymnasium/vector/async_vector_env.py", line 313, in _worker_shared_memory
    pipe.send((None, False))
  File "/home/zzydty/miniconda3/envs/safety/lib/python3.8/multiprocessing/connection.py", line 206, in send
    self._send_bytes(_ForkingPickler.dumps(obj))
  File "/home/zzydty/miniconda3/envs/safety/lib/python3.8/multiprocessing/connection.py", line 411, in _send_bytes
    self._send(header + buf)
  File "/home/zzydty/miniconda3/envs/safety/lib/python3.8/multiprocessing/connection.py", line 368, in _send
    n = write(self._handle, buf)
BrokenPipeError: [Errno 32] Broken pipe
Process Worker<SafetyAsyncVectorEnv>-2:
Traceback (most recent call last):
  File "/home/zzydty/sim/safety-gymnasium-main/safety_gymnasium/vector/async_vector_env.py", line 253, in _worker_shared_memory
    command, data = pipe.recv()
  File "/home/zzydty/miniconda3/envs/safety/lib/python3.8/multiprocessing/connection.py", line 250, in recv
    buf = self._recv_bytes()
  File "/home/zzydty/miniconda3/envs/safety/lib/python3.8/multiprocessing/connection.py", line 414, in _recv_bytes
    buf = self._recv(4)
  File "/home/zzydty/miniconda3/envs/safety/lib/python3.8/multiprocessing/connection.py", line 383, in _recv
    raise EOFError
EOFError

During handling of the above exception, another exception occurred:

Traceback (most recent call last):
  File "/home/zzydty/miniconda3/envs/safety/lib/python3.8/multiprocessing/process.py", line 315, in _bootstrap
    self.run()
  File "/home/zzydty/miniconda3/envs/safety/lib/python3.8/multiprocessing/process.py", line 108, in run
    self._target(*self._args, **self._kwargs)
  File "/home/zzydty/sim/safety-gymnasium-main/safety_gymnasium/vector/async_vector_env.py", line 313, in _worker_shared_memory
    pipe.send((None, False))
  File "/home/zzydty/miniconda3/envs/safety/lib/python3.8/multiprocessing/connection.py", line 206, in send
    self._send_bytes(_ForkingPickler.dumps(obj))
  File "/home/zzydty/miniconda3/envs/safety/lib/python3.8/multiprocessing/connection.py", line 411, in _send_bytes
    self._send(header + buf)
  File "/home/zzydty/miniconda3/envs/safety/lib/python3.8/multiprocessing/connection.py", line 368, in _send
    n = write(self._handle, buf)
BrokenPipeError: [Errno 32] Broken pipe
Process Worker<SafetyAsyncVectorEnv>-1:
Traceback (most recent call last):
  File "/home/zzydty/sim/safety-gymnasium-main/safety_gymnasium/vector/async_vector_env.py", line 253, in _worker_shared_memory
    command, data = pipe.recv()
  File "/home/zzydty/miniconda3/envs/safety/lib/python3.8/multiprocessing/connection.py", line 250, in recv
    buf = self._recv_bytes()
  File "/home/zzydty/miniconda3/envs/safety/lib/python3.8/multiprocessing/connection.py", line 414, in _recv_bytes
    buf = self._recv(4)
  File "/home/zzydty/miniconda3/envs/safety/lib/python3.8/multiprocessing/connection.py", line 383, in _recv
    raise EOFError
EOFError

During handling of the above exception, another exception occurred:

Traceback (most recent call last):
  File "/home/zzydty/miniconda3/envs/safety/lib/python3.8/multiprocessing/process.py", line 315, in _bootstrap
    self.run()
  File "/home/zzydty/miniconda3/envs/safety/lib/python3.8/multiprocessing/process.py", line 108, in run
    self._target(*self._args, **self._kwargs)
  File "/home/zzydty/sim/safety-gymnasium-main/safety_gymnasium/vector/async_vector_env.py", line 313, in _worker_shared_memory
    pipe.send((None, False))
  File "/home/zzydty/miniconda3/envs/safety/lib/python3.8/multiprocessing/connection.py", line 206, in send
    self._send_bytes(_ForkingPickler.dumps(obj))
  File "/home/zzydty/miniconda3/envs/safety/lib/python3.8/multiprocessing/connection.py", line 411, in _send_bytes
    self._send(header + buf)
  File "/home/zzydty/miniconda3/envs/safety/lib/python3.8/multiprocessing/connection.py", line 368, in _send
    n = write(self._handle, buf)
BrokenPipeError: [Errno 32] Broken pipe
Process Worker<SafetyAsyncVectorEnv>-0:
Traceback (most recent call last):
  File "/home/zzydty/sim/safety-gymnasium-main/safety_gymnasium/vector/async_vector_env.py", line 253, in _worker_shared_memory
    command, data = pipe.recv()
  File "/home/zzydty/miniconda3/envs/safety/lib/python3.8/multiprocessing/connection.py", line 250, in recv
    buf = self._recv_bytes()
  File "/home/zzydty/miniconda3/envs/safety/lib/python3.8/multiprocessing/connection.py", line 414, in _recv_bytes
    buf = self._recv(4)
  File "/home/zzydty/miniconda3/envs/safety/lib/python3.8/multiprocessing/connection.py", line 383, in _recv
    raise EOFError
EOFError

During handling of the above exception, another exception occurred:

Traceback (most recent call last):
  File "/home/zzydty/miniconda3/envs/safety/lib/python3.8/multiprocessing/process.py", line 315, in _bootstrap
    self.run()
  File "/home/zzydty/miniconda3/envs/safety/lib/python3.8/multiprocessing/process.py", line 108, in run
    self._target(*self._args, **self._kwargs)
  File "/home/zzydty/sim/safety-gymnasium-main/safety_gymnasium/vector/async_vector_env.py", line 313, in _worker_shared_memory
    pipe.send((None, False))
  File "/home/zzydty/miniconda3/envs/safety/lib/python3.8/multiprocessing/connection.py", line 206, in send
    self._send_bytes(_ForkingPickler.dumps(obj))
  File "/home/zzydty/miniconda3/envs/safety/lib/python3.8/multiprocessing/connection.py", line 411, in _send_bytes
    self._send(header + buf)
  File "/home/zzydty/miniconda3/envs/safety/lib/python3.8/multiprocessing/connection.py", line 368, in _send
    n = write(self._handle, buf)
BrokenPipeError: [Errno 32] Broken pipe
